<?xml version='1.0'?>

<robot name="saminda_bot" xmlns:xacro="http://www.ros.org/wiki/xacro">

    <xacro:include filename="$(find udacity_bot)/urdf/saminda_bot.gazebo"/>

    <material name="red">
        <color rgba="1 0 0 1"/>
    </material>

    <material name="green">
        <color rgba="0 1 0 1"/>
    </material>

    <material name="blue">
        <color rgba="0 0 1 1"/>
    </material>

    <link name="robot_footprint"></link>

    <joint name="robot_footprint_joint" type="fixed">
        <origin xyz="0 0 0" rpy="0 0 0"/>
        <parent link="robot_footprint"/>
        <child link="chassis"/>
    </joint>

    <link name='chassis'>
        <pose>0 0 0.1 0 0 0</pose>

        <inertial>
            <mass value="5.0"/>
            <origin xyz="0.0 0 0" rpy=" 0 0 0"/>
            <inertia
                    ixx="0.1" ixy="0" ixz="0"
                    iyy="0.1" iyz="0"
                    izz="0.1"
            />
        </inertial>

        <collision name='collision'>
            <origin xyz="0 0 0" rpy=" 0 0 0"/>
            <geometry>
                <box size="0.4 0.2 0.05"/>
            </geometry>
        </collision>

        <visual name='visual'>
            <origin xyz="0 0 0" rpy=" 0 0 0"/>
            <geometry>
                <box size="0.4 0.2 0.05"/>
            </geometry>
            <material name="blue"/>
        </visual>
    </link>

    <link name='right_front_wheel'>
        <inertial>
            <mass value="0.2"/>
             <origin xyz="0.0 0 0" rpy="1.5707 0 0"/>
            <inertia
                    ixx="0.005" ixy="0" ixz="0"
                    iyy="0.005" iyz="0"
                    izz="0.005"
            />
        </inertial>

        <collision name='collision'>
             <origin xyz="0 0 0" rpy="1.5707 0 0"/>
            <geometry>
                <cylinder length="0.0375" radius="0.055"/>
            </geometry>
        </collision>

        <visual name='visual'>
             <origin xyz="0 0 0" rpy="1.5707 0 0"/>
            <geometry>
                <cylinder length="0.0375" radius="0.055"/>
            </geometry>
            <material name="green"/>
        </visual>
    </link>


    <link name='left_front_wheel'>
        <inertial>
            <mass value="0.2"/>
             <origin xyz="0.0 0 0" rpy="1.5707 0 0"/>
            <inertia
                    ixx="0.005" ixy="0" ixz="0"
                    iyy="0.005" iyz="0"
                    izz="0.005"
            />
        </inertial>

        <collision name='collision'>
             <origin xyz="0 0 0" rpy="1.5707 0 0"/>
            <geometry>
                <cylinder length="0.0375" radius="0.055"/>
            </geometry>
        </collision>

        <visual name='visual'>
             <origin xyz="0 0 0" rpy="1.5707 0 0"/>
            <geometry>
                <cylinder length="0.0375" radius="0.055"/>
            </geometry>
            <material name="green"/>
        </visual>
    </link>


    <link name='right_rear_wheel'>
        <inertial>
            <mass value="0.2"/>
             <origin xyz="0.0 0 0" rpy="1.5707 0 0"/>
            <inertia
                    ixx="0.005" ixy="0" ixz="0"
                    iyy="0.005" iyz="0"
                    izz="0.005"
            />
        </inertial>

        <collision name='collision'>
             <origin xyz="0 0 0" rpy="1.5707 0 0"/>
            <geometry>
                <cylinder length="0.0375" radius="0.055"/>
            </geometry>
        </collision>

        <visual name='visual'>
             <origin xyz="0 0 0" rpy="1.5707 0 0"/>
            <geometry>
                <cylinder length="0.0375" radius="0.055"/>
            </geometry>
            <material name="green"/>
        </visual>
    </link>

    <link name='left_rear_wheel'>
        <inertial>
            <mass value="0.2"/>
             <origin xyz="0.0 0 0" rpy="1.5707 0 0"/>
            <inertia
                    ixx="0.005" ixy="0" ixz="0"
                    iyy="0.005" iyz="0"
                    izz="0.005"
            />
        </inertial>

        <collision name='collision'>
             <origin xyz="0 0 0" rpy="1.5707 0 0"/>
            <geometry>
                <cylinder length="0.0375" radius="0.055"/>
            </geometry>
        </collision>

        <visual name='visual'>
             <origin xyz="0 0 0" rpy="1.5707 0 0"/>
            <geometry>
                <cylinder length="0.0375" radius="0.055"/>
            </geometry>
            <material name="green"/>
        </visual>
    </link>


    <link name='camera'>
        <inertial>
            <mass value="0.1"/>
            <origin xyz="0.0 0 0" rpy="0 0 0"/>
            <inertia
                    ixx="1e-6" ixy="0" ixz="0"
                    iyy="1e-6" iyz="0"
                    izz="1e-6"
            />
        </inertial>

        <collision name='camera_collision'>
            <origin xyz="0 0 0" rpy="0 0 0"/>
            <geometry>
                <box size="0.05 0.05 0.05"/>
            </geometry>
        </collision>

        <visual name='camera_visual'>
            <origin xyz="0 0 0" rpy="0 0 0"/>
            <geometry>
                <box size="0.05 0.05 0.05"/>
            </geometry>
            <material name="red"/>
        </visual>
    </link>


    <link name='hokuyo'>
        <inertial>
            <mass value="0.1"/>
            <origin xyz="0.0 0 0" rpy="0 0 0"/>
            <inertia
                    ixx="1e-6" ixy="0" ixz="0"
                    iyy="1e-6" iyz="0"
                    izz="1e-6"
            />
        </inertial>

        <collision name='hokuyo_collision'>
            <origin xyz="0 0 0" rpy="0 0 0"/>
            <geometry>
                <box size="0.1 0.1 0.1"/>
            </geometry>
        </collision>

        <visual name='hokuyo_visual'>
            <origin xyz="0 0 0" rpy="0 0 0"/>
            <geometry>
                <mesh filename="package://udacity_bot/meshes/hokuyo.dae"/>
            </geometry>
        </visual>
    </link>

    <joint type="continuous" name="right_front">
        <origin xyz="0.15 -0.13 0" rpy="0 0 0"/>
        <child link="right_front_wheel"/>
        <parent link="chassis"/>
        <axis xyz="0 1 0" rpy="0 0 0" use_parent_model_frame="true"/>
        <limit effort="10000" velocity="1000"/>
        <dynamics damping="1.0" friction="1.0"/>
    </joint>

    <joint type="continuous" name="right_rear">
        <origin xyz="-0.15 -0.13 0" rpy="0 0 0"/>
        <child link="right_rear_wheel"/>
        <parent link="chassis"/>
        <axis xyz="0 1 0" rpy="0 0 0" use_parent_model_frame="true"/>
        <limit effort="10000" velocity="1000"/>
        <dynamics damping="1.0" friction="1.0"/>
    </joint>

    <joint type="continuous" name="left_front">
        <origin xyz="0.15 0.13 0" rpy="0 0 0"/>
        <child link="left_front_wheel"/>
        <parent link="chassis"/>
        <axis xyz="0 1 0" rpy="0 0 0" use_parent_model_frame="true"/>
        <limit effort="10000" velocity="1000"/>
        <dynamics damping="1.0" friction="1.0"/>
    </joint>

    <joint type="continuous" name="left_rear">
        <origin xyz="-0.15 0.13 0" rpy="0 0 0"/>
        <child link="left_rear_wheel"/>
        <parent link="chassis"/>
        <axis xyz="0 1 0" rpy="0 0 0" use_parent_model_frame="true"/>
        <limit effort="10000" velocity="1000"/>
        <dynamics damping="1.0" friction="1.0"/>
    </joint>

    <joint type="fixed" name="camera_joint">
        <origin xyz="0.2 0 0" rpy="0 0 0"/>
        <child link="camera"/>
        <parent link="chassis"/>
    </joint>

    <joint type="fixed" name="hokuyo_joint">
        <origin xyz="0.18 0 0.05" rpy="0 0 0"/>
        <child link="hokuyo"/>
        <parent link="chassis"/>
    </joint>

</robot>
